<?xml version="1.0" ?>
<!-- =================================================================================== -->
<!-- |    This document was autogenerated by xacro from /home/sumit-jangra/ros2_ws/src/my_arm_description/urdf/simple_arm_moveit_clean.urdf.xacro | -->
<!-- |    EDITING THIS FILE BY HAND IS NOT RECOMMENDED                                 | -->
<!-- =================================================================================== -->
<robot name="simple_arm">
  <!-- BASE LINK -->
  <link name="base_link">
    <visual>
      <geometry>
        <cylinder length="0.2" radius="0.2"/>
      </geometry>
      <material name="red">
        <color rgba="1 0 0 1"/>
      </material>
    </visual>
  </link>
  <!-- LINK 1 -->
  <link name="link1">
    <visual>
      <origin rpy="0 0 0" xyz="0 0 0.5"/>
      <geometry>
        <box size="0.1 0.1 1.0"/>
      </geometry>
      <material name="blue">
        <color rgba="0 0 1 1"/>
      </material>
    </visual>
  </link>
  <!-- LINK 2 -->
  <link name="link2">
    <visual>
      <origin rpy="0 0 0" xyz="0 0 0.4"/>
      <geometry>
        <box size="0.08 0.08 0.8"/>
      </geometry>
      <material name="green">
        <color rgba="0 1 0 1"/>
      </material>
    </visual>
  </link>
  <!-- LINK 3 -->
  <link name="link3">
    <visual>
      <origin rpy="0 0 0" xyz="0 0 0.3"/>
      <geometry>
        <box size="0.06 0.06 0.6"/>
      </geometry>
      <material name="yellow">
        <color rgba="1 1 0 1"/>
      </material>
    </visual>
  </link>
  <!-- LINK 4 -->
  <link name="link4">
    <visual>
      <origin rpy="0 0 0" xyz="0 0 0.15"/>
      <geometry>
        <box size="0.05 0.05 0.3"/>
      </geometry>
      <material name="purple">
        <color rgba="0.5 0 0.5 1"/>
      </material>
    </visual>
  </link>
  <!-- LINK 5 -->
  <link name="link5">
    <visual>
      <origin rpy="0 0 0" xyz="0 0 0.1"/>
      <geometry>
        <box size="0.045 0.045 0.2"/>
      </geometry>
      <material name="orange">
        <color rgba="1 0.5 0 1"/>
      </material>
    </visual>
  </link>
  <!-- LINK 6 -->
  <link name="link6">
    <visual>
      <origin rpy="0 0 0" xyz="0 0 0.075"/>
      <geometry>
        <box size="0.04 0.04 0.15"/>
      </geometry>
      <material name="cyan">
        <color rgba="0 1 1 1"/>
      </material>
    </visual>
  </link>
  <!-- END EFFECTOR -->
  <link name="end_effector_link">
    <visual>
      <origin rpy="0 0 0" xyz="0 0 0.05"/>
      <geometry>
        <box size="0.12 0.12 0.1"/>
      </geometry>
      <material name="black">
        <color rgba="0 0 0 1"/>
      </material>
    </visual>
  </link>
  <!-- JOINT 1: BASE ROTATION -->
  <joint name="base_to_link1_joint" type="revolute">
    <parent link="base_link"/>
    <child link="link1"/>
    <origin rpy="0 0 0" xyz="0 0 0.1"/>
    <axis xyz="0 0 1"/>
    <limit effort="10" lower="-3.14" upper="3.14" velocity="1"/>
  </joint>
  <!-- JOINT 2: SHOULDER -->
  <joint name="shoulder_joint" type="revolute">
    <parent link="link1"/>
    <child link="link2"/>
    <origin rpy="0 0 0" xyz="0 0 1.0"/>
    <axis xyz="0 1 0"/>
    <limit effort="10" lower="-1.57" upper="1.57" velocity="1"/>
  </joint>
  <!-- JOINT 3: ELBOW -->
  <joint name="elbow_joint" type="revolute">
    <parent link="link2"/>
    <child link="link3"/>
    <origin rpy="0 0 0" xyz="0 0 0.8"/>
    <axis xyz="0 1 0"/>
    <limit effort="10" lower="-1.57" upper="1.57" velocity="1"/>
  </joint>
  <!-- JOINT 4: WRIST PITCH -->
  <joint name="wrist_pitch_joint" type="revolute">
    <parent link="link3"/>
    <child link="link4"/>
    <origin rpy="0 0 0" xyz="0 0 0.6"/>
    <axis xyz="0 1 0"/>
    <limit effort="10" lower="-1.57" upper="1.57" velocity="1"/>
  </joint>
  <!-- JOINT 5: WRIST ROLL -->
  <joint name="wrist_roll_joint" type="revolute">
    <parent link="link4"/>
    <child link="link5"/>
    <origin rpy="0 0 0" xyz="0 0 0.3"/>
    <axis xyz="0 0 1"/>
    <limit effort="10" lower="-3.14" upper="3.14" velocity="1"/>
  </joint>
  <!-- JOINT 6: WRIST YAW -->
  <joint name="wrist_yaw_joint" type="revolute">
    <parent link="link5"/>
    <child link="link6"/>
    <origin rpy="0 0 0" xyz="0 0 0.2"/>
    <axis xyz="1 0 0"/>
    <limit effort="10" lower="-3.14" upper="3.14" velocity="1"/>
  </joint>
  <!-- FIXED JOINT TO END EFFECTOR -->
  <joint name="link6_to_end_effector" type="fixed">
    <parent link="link6"/>
    <child link="end_effector_link"/>
    <origin rpy="0 0 0" xyz="0 0 0.15"/>
  </joint>
</robot>
